<mujoco model="iiwa14_allegro_right_scene">
  <compiler angle="radian" autolimits="true"/>

  <option integrator="implicitfast" cone="elliptic" impratio="10"/>

  <statistic center="0.2 0 0.2" extent="1.0"/>

  <visual>
    <headlight diffuse="0.6 0.6 0.6" ambient="0.3 0.3 0.3" specular="0 0 0"/>
    <rgba haze="0.15 0.25 0.35 1"/>
    <global azimuth="-120" elevation="-20"/>
  </visual>

  <asset>
    <texture type="skybox" builtin="gradient" rgb1="0.3 0.5 0.7" rgb2="0 0 0" width="512" height="3072"/>
    <texture type="2d" name="groundplane" builtin="checker" mark="edge" rgb1="0.2 0.3 0.4" rgb2="0.1 0.2 0.3"
      markrgb="0.8 0.8 0.8" width="300" height="300"/>
    <material name="groundplane" texture="groundplane" texuniform="true" texrepeat="5 5" reflectance="0.2"/>

    <material class="iiwa" name="gray" rgba="0.4 0.4 0.4 1"/>
    <material class="iiwa" name="light_gray" rgba="0.6 0.6 0.6 1"/>
    <material class="iiwa" name="black" rgba="0 0 0 1"/>
    <material class="iiwa" name="orange" rgba="1 0.423529 0.0392157 1"/>

    <material name="allegro_black" rgba="0.2 0.2 0.2 1"/>
    <material name="allegro_white" rgba="0.9 0.9 0.9 1"/>

    <mesh file="kuka_iiwa_14/assets/link_0.obj"/>
    <mesh file="kuka_iiwa_14/assets/link_1.obj"/>
    <mesh file="kuka_iiwa_14/assets/link_2_orange.obj"/>
    <mesh file="kuka_iiwa_14/assets/link_2_grey.obj"/>
    <mesh file="kuka_iiwa_14/assets/link_3.obj"/>
    <mesh file="kuka_iiwa_14/assets/band.obj"/>
    <mesh file="kuka_iiwa_14/assets/kuka.obj"/>
    <mesh file="kuka_iiwa_14/assets/link_4_orange.obj"/>
    <mesh file="kuka_iiwa_14/assets/link_4_grey.obj"/>
    <mesh file="kuka_iiwa_14/assets/link_5.obj"/>
    <mesh file="kuka_iiwa_14/assets/link_6_orange.obj"/>
    <mesh file="kuka_iiwa_14/assets/link_6_grey.obj"/>
    <mesh file="kuka_iiwa_14/assets/link_7.obj"/>

    <mesh file="wonik_allegro/assets/base_link.stl"/>
    <mesh file="wonik_allegro/assets/link_0.0.stl"/>
    <mesh file="wonik_allegro/assets/link_1.0.stl"/>
    <mesh file="wonik_allegro/assets/link_2.0.stl"/>
    <mesh file="wonik_allegro/assets/link_3.0.stl"/>
    <mesh file="wonik_allegro/assets/link_3.0_tip.stl"/>
    <mesh file="wonik_allegro/assets/link_12.0_right.stl"/>
    <mesh file="wonik_allegro/assets/link_13.0.stl"/>
    <mesh file="wonik_allegro/assets/link_14.0.stl"/>
    <mesh file="wonik_allegro/assets/link_15.0.stl"/>
    <mesh file="wonik_allegro/assets/link_15.0_tip.stl"/>
  </asset>

  <default>
    <default class="iiwa">
      <material specular="0.5" shininess="0.25"/>
      <joint axis="0 0 1"/>
      <general gaintype="fixed" biastype="affine" gainprm="2000" biasprm="0 -2000 -200"/>
      <default class="joint1">
        <joint range="-2.96706 2.96706"/>
        <general ctrlrange="-2.96706 2.96706"/>
        <default class="joint2">
          <joint range="-2.0944 2.0944"/>
          <general ctrlrange="-2.0944 2.0944"/>
        </default>
      </default>
      <default class="joint3">
        <joint range="-3.05433 3.05433"/>
        <general ctrlrange="-3.05433 3.05433"/>
      </default>
      <default class="visual">
        <geom type="mesh" contype="0" conaffinity="0" group="2" material="gray"/>
      </default>
      <default class="collision">
        <geom group="3"/>
      </default>
      <site size="0.001" rgba="1 0 0 1" group="4"/>
    </default>

    <default class="allegro_right">
      <joint axis="0 1 0" damping=".1"/>
      <position kp="1"/>
      <geom density="800"/>

      <default class="allegro_visual">
        <geom type="mesh" contype="0" conaffinity="0" group="2" material="allegro_black"/>
        <default class="palm_visual">
          <geom mesh="base_link"/>
        </default>
        <default class="base_visual">
          <geom mesh="link_0.0"/>
        </default>
        <default class="proximal_visual">
          <geom mesh="link_1.0"/>
        </default>
        <default class="medial_visual">
          <geom mesh="link_2.0"/>
        </default>
        <default class="distal_visual">
          <geom mesh="link_3.0"/>
        </default>
        <default class="fingertip_visual">
          <geom pos="0 0 0.0267" material="allegro_white" mesh="link_3.0_tip"/>
        </default>
        <default class="thumbtip_visual">
          <geom pos="0 0 0.0423" material="allegro_white" mesh="link_15.0_tip"/>
        </default>
      </default>

      <default class="allegro_collision">
        <geom group="3" type="box" mass="0"/>
        <default class="palm_collision">
          <geom size="0.0204 0.0565 0.0475" pos="-0.0093 0 -0.0475"/>
        </default>
        <default class="base_collision">
          <geom size="0.0098 0.01375 0.0082" pos="0 0 0.0082"/>
          <default class="thumb_base_collision">
            <geom size="0.0179 0.017 0.02275" pos="-0.0179 0.009 0.0145"/>
          </default>
        </default>
        <default class="proximal_collision">
          <geom size="0.0098 0.01375 0.027" pos="0 0 0.027"/>
          <default class="thumb_proximal_collision">
            <geom size="0.0098 0.01375 0.00885" pos="0 0 0.00885"/>
          </default>
        </default>
        <default class="medial_collision">
          <geom size="0.0098 0.01375 0.0192" pos="0 0 0.0192"/>
          <default class="thumb_medial_collision">
            <geom size="0.0098 0.01375 0.0257" pos="0 0 0.0257"/>
          </default>
        </default>
        <default class="distal_collision">
          <geom size="0.0098 0.01375 0.008" pos="0 0 0.008"/>
          <default class="thumb_distal_collision">
            <geom size="0.0098 0.01375 0.0157" pos="0 0 0.0157"/>
          </default>
        </default>
        <default class="fingertip_collision">
          <geom type="capsule" size="0.012 0.01" pos="0 0 0.019"/>
          <default class="thumbtip_collision">
            <geom type="capsule" size="0.012 0.008" pos="0 0 0.035"/>
          </default>
        </default>
      </default>

      <default class="base">
        <joint axis="0 0 1" range="-0.47 0.47"/>
        <position ctrlrange="-0.47 0.47"/>
      </default>
      <default class="proximal">
        <joint range="-0.196 1.61"/>
        <position ctrlrange="-0.196 1.61"/>
      </default>
      <default class="medial">
        <joint range="-0.174 1.709"/>
        <position ctrlrange="-0.174 1.709"/>
      </default>
      <default class="distal">
        <joint range="-0.227 1.618"/>
        <position ctrlrange="-0.227 1.618"/>
      </default>
      <default class="thumb_base">
        <joint axis="-1 0 0" range="0.263 1.396"/>
        <position ctrlrange="0.263 1.396"/>
      </default>
      <default class="thumb_proximal">
        <joint axis="0 0 1" range="-0.105 1.163"/>
        <position ctrlrange="-0.105 1.163"/>
      </default>
      <default class="thumb_medial">
        <joint range="-0.189 1.644"/>
        <position ctrlrange="-0.189 1.644"/>
      </default>
      <default class="thumb_distal">
        <joint range="-0.162 1.719"/>
        <position ctrlrange="-0.162 1.719"/>
      </default>
    </default>
  </default>

  <worldbody>
    <light pos="0 0 1.5" dir="0 0 -1" directional="true"/>
    <geom name="floor" size="0 0 0.05" type="plane" material="groundplane"/>

    <light name="top" pos="0 0 2" mode="trackcom"/>
    <body name="base" childclass="iiwa">
      <inertial mass="5" pos="-0.1 0 0.07" diaginertia="0.05 0.06 0.03"/>
      <geom class="visual" mesh="link_0"/>
      <geom class="collision" size="0.12" pos="0 0 0.03"/>
      <geom class="collision" size="0.08" pos="-0.08 0 0.103"/>
      <geom class="collision" size="0.08" pos="-0.08 0 0.04"/>
      <geom class="collision" size="0.1" pos="0 0 0.14"/>
      <body name="link1" pos="0 0 0.1575">
        <inertial mass="5.76" pos="0 -0.03 0.12" diaginertia="0.0333 0.033 0.0123"/>
        <joint name="joint1" class="joint1"/>
        <geom class="visual" mesh="link_1"/>
        <geom class="collision" size="0.08" pos="0 0 -0.0005"/>
        <geom class="collision" size="0.075" pos="0.01 -0.025 0.0425"/>
        <geom class="collision" size="0.075" pos="-0.01 -0.025 0.0425"/>
        <geom class="collision" size="0.07" pos="0.01 -0.045 0.1025"/>
        <geom class="collision" size="0.07" pos="-0.01 -0.045 0.1025"/>
        <body name="link2" pos="0 0 0.2025" quat="0 0 1 1">
          <inertial mass="6.35" pos="0.0003 0.059 0.042" diaginertia="0.0305 0.0304 0.011" quat="0 0 1 1"/>
          <joint name="joint2" class="joint2"/>
          <geom class="visual" material="orange" mesh="link_2_orange"/>
          <geom class="visual" mesh="link_2_grey"/>
          <geom class="collision" size="0.095" pos="0 0 -0.01"/>
          <geom class="collision" size="0.09" pos="0 0 0.045"/>
          <geom class="collision" size="0.07" pos="-0.01 0.04 0.054"/>
          <geom class="collision" size="0.065" pos="-0.01 0.09 0.04"/>
          <geom class="collision" size="0.065" pos="-0.01 0.13 0.02"/>
          <geom class="collision" size="0.07" pos="0.01 0.04 0.054"/>
          <geom class="collision" size="0.065" pos="0.01 0.09 0.04"/>
          <geom class="collision" size="0.065" pos="0.01 0.13 0.02"/>
          <geom class="collision" size="0.075" pos="0 0.18 0"/>
          <body name="link3" pos="0 0.2045 0" quat="0 0 1 1">
            <inertial mass="3.5" pos="0 0.03 0.13" diaginertia="0.025 0.0238 0.0076"/>
            <joint name="joint3" class="joint1"/>
            <geom class="visual" mesh="link_3"/>
            <geom class="visual" material="light_gray" mesh="band"/>
            <geom class="visual" material="black" mesh="kuka"/>
            <geom class="collision" size="0.075" pos="0 0 0.0355"/>
            <geom class="collision" size="0.06" pos="0.01 0.023 0.0855"/>
            <geom class="collision" size="0.055" pos="0.01 0.048 0.1255"/>
            <geom class="collision" size="0.06" pos="0.01 0.056 0.1755"/>
            <geom class="collision" size="0.06" pos="-0.01 0.023 0.0855"/>
            <geom class="collision" size="0.055" pos="-0.01 0.048 0.1255"/>
            <geom class="collision" size="0.06" pos="-0.01 0.056 0.1755"/>
            <geom class="collision" size="0.075" pos="0 0.045 0.2155"/>
            <geom class="collision" size="0.075" pos="0 0 0.2155"/>
            <body name="link4" pos="0 0 0.2155" quat="1 1 0 0">
              <inertial mass="3.5" pos="0 0.067 0.034" diaginertia="0.017 0.0164 0.006" quat="1 1 0 0"/>
              <joint name="joint4" class="joint2"/>
              <geom class="visual" material="orange" mesh="link_4_orange"/>
              <geom class="visual" mesh="link_4_grey"/>
              <geom class="collision" size="0.078" pos="0 0.01 0.046"/>
              <geom class="collision" size="0.06" pos="0.01 0.06 0.052"/>
              <geom class="collision" size="0.065" pos="0.01 0.12 0.034"/>
              <geom class="collision" size="0.06" pos="-0.01 0.06 0.052"/>
              <geom class="collision" size="0.065" pos="-0.01 0.12 0.034"/>
              <geom class="collision" size="0.075" pos="0 0.184 0"/>
              <body name="link5" pos="0 0.1845 0" quat="0 0 1 1">
                <inertial mass="3.5" pos="0.0001 0.021 0.076" diaginertia="0.01 0.0087 0.00449"/>
                <joint name="joint5" class="joint1"/>
                <geom class="visual" mesh="link_5"/>
                <geom class="visual" material="light_gray" mesh="band"/>
                <geom class="visual" material="black" mesh="kuka"/>
                <geom class="collision" size="0.075" pos="0 0 0.0335"/>
                <geom class="collision" size="0.05" pos="-0.012 0.031 0.0755"/>
                <geom class="collision" size="0.05" pos="0.012 0.031 0.0755"/>
                <geom class="collision" size="0.04" pos="-0.012 0.06 0.1155"/>
                <geom class="collision" size="0.04" pos="0.012 0.06 0.1155"/>
                <geom class="collision" size="0.04" pos="-0.01 0.065 0.1655"/>
                <geom class="collision" size="0.04" pos="0.01 0.065 0.1655"/>
                <geom class="collision" size="0.035" pos="-0.012 0.065 0.1855"/>
                <geom class="collision" size="0.035" pos="0.012 0.065 0.1855"/>
                <body name="link6" pos="0 0 0.2155" quat="1 1 0 0">
                  <inertial mass="1.8" pos="0 0.0006 0.0004" diaginertia="0.0049 0.0047 0.0036" quat="1 1 0 0"/>
                  <joint name="joint6" class="joint2"/>
                  <geom class="visual" material="orange" mesh="link_6_orange"/>
                  <geom class="visual" mesh="link_6_grey"/>
                  <geom class="collision" size="0.055" pos="0 0 -0.059"/>
                  <geom class="collision" size="0.065" pos="0 -0.03 0.011"/>
                  <geom class="collision" size="0.08"/>
                  <body name="link7" pos="0 0.077 0" quat="0 0 1 1">
                    <inertial mass="1.2" pos="0 0 0.02" diaginertia="0.001 0.001 0.001"/>
                    <joint name="joint7" class="joint3"/>
                    <geom class="visual" mesh="link_7"/>
                    <geom class="collision" size="0.06" pos="0 0 0.001"/>
                    <site pos="0 0 0.045" name="attachment_site"/>
                    <body name="allegro_mount" pos="0.01 0 0.14" quat="0 1 0 1">
                      <body name="palm" quat="0 1 0 1" childclass="allegro_right">
                        <geom class="palm_visual" mesh="base_link"/>
                        <geom class="palm_collision"/>
                        <body name="ff_base" pos="0 0.0435 -0.001542" quat="0.999048 -0.0436194 0 0">
                          <joint name="ffj0" class="base"/>
                          <geom class="base_visual"/>
                          <geom class="base_collision"/>
                          <body name="ff_proximal" pos="0 0 0.0164">
                            <joint name="ffj1" class="proximal"/>
                            <geom class="proximal_visual"/>
                            <geom class="proximal_collision"/>
                            <body name="ff_medial" pos="0 0 0.054">
                              <joint name="ffj2" class="medial"/>
                              <geom class="medial_visual"/>
                              <geom class="medial_collision"/>
                              <body name="ff_distal" pos="0 0 0.0384">
                                <joint name="ffj3" class="distal"/>
                                <geom class="distal_visual"/>
                                <geom class="distal_collision"/>
                                <body name="ff_tip">
                                  <geom class="fingertip_visual"/>
                                  <geom class="fingertip_collision"/>
                                </body>
                              </body>
                            </body>
                          </body>
                        </body>
                        <body name="mf_base" pos="0 0 0.0007">
                          <joint name="mfj0" class="base"/>
                          <geom class="base_visual"/>
                          <geom class="base_collision"/>
                          <body name="mf_proximal" pos="0 0 0.0164">
                            <joint name="mfj1" class="proximal"/>
                            <geom class="proximal_visual"/>
                            <geom class="proximal_collision"/>
                            <body name="mf_medial" pos="0 0 0.054">
                              <joint name="mfj2" class="medial"/>
                              <geom class="medial_visual"/>
                              <geom class="medial_collision"/>
                              <body name="mf_distal" pos="0 0 0.0384">
                                <joint name="mfj3" class="distal"/>
                                <geom class="distal_visual"/>
                                <geom class="distal_collision"/>
                                <body name="mf_tip">
                                  <geom class="fingertip_visual"/>
                                  <geom class="fingertip_collision"/>
                                </body>
                              </body>
                            </body>
                          </body>
                        </body>
                        <body name="rf_base" pos="0 -0.0435 -0.001542" quat="0.999048 0.0436194 0 0">
                          <joint name="rfj0" class="base"/>
                          <geom class="base_visual"/>
                          <geom class="base_collision"/>
                          <body name="rf_proximal" pos="0 0 0.0164">
                            <joint name="rfj1" class="proximal"/>
                            <geom class="proximal_visual"/>
                            <geom class="proximal_collision"/>
                            <body name="rf_medial" pos="0 0 0.054">
                              <joint name="rfj2" class="medial"/>
                              <geom class="medial_visual"/>
                              <geom class="medial_collision"/>
                              <body name="rf_distal" pos="0 0 0.0384">
                                <joint name="rfj3" class="distal"/>
                                <geom class="distal_visual"/>
                                <geom class="distal_collision"/>
                                <body name="rf_tip">
                                  <geom class="fingertip_visual"/>
                                  <geom class="fingertip_collision"/>
                                </body>
                              </body>
                            </body>
                          </body>
                        </body>
                        <body name="th_base" pos="-0.0182 0.019333 -0.045987" quat="0.477714 -0.521334 -0.521334 -0.477714">
                          <joint name="thj0" class="thumb_base"/>
                          <geom class="allegro_visual" mesh="link_12.0_right"/>
                          <geom class="thumb_base_collision"/>
                          <body name="th_proximal" pos="-0.027 0.005 0.0399">
                            <joint name="thj1" class="thumb_proximal"/>
                            <geom class="allegro_visual" mesh="link_13.0"/>
                            <geom class="thumb_proximal_collision"/>
                            <body name="th_medial" pos="0 0 0.0177">
                              <joint name="thj2" class="thumb_medial"/>
                              <geom class="allegro_visual" mesh="link_14.0"/>
                              <geom class="thumb_medial_collision"/>
                              <body name="th_distal" pos="0 0 0.0514">
                                <joint name="thj3" class="thumb_distal"/>
                                <geom class="allegro_visual" mesh="link_15.0"/>
                                <geom class="thumb_distal_collision"/>
                                <body name="th_tip">
                                  <geom class="thumbtip_visual"/>
                                  <geom class="thumbtip_collision"/>
                                </body>
                              </body>
                            </body>
                          </body>
                        </body>
                      </body>
                    </body>
                  </body>
                </body>
              </body>
            </body>
          </body>
        </body>
      </body>
    </body>
  </worldbody>

  <contact>
    <exclude body1="base" body2="link1"/>
    <exclude body1="base" body2="link2"/>
    <exclude body1="base" body2="link3"/>
    <exclude body1="link1" body2="link3"/>
    <exclude body1="link3" body2="link5"/>
    <exclude body1="link4" body2="link7"/>
    <exclude body1="link5" body2="link7"/>
    <exclude body1="link7" body2="palm"/>

    <exclude body1="palm" body2="ff_base"/>
    <exclude body1="palm" body2="mf_base"/>
    <exclude body1="palm" body2="rf_base"/>
    <exclude body1="palm" body2="th_base"/>
    <exclude body1="palm" body2="th_proximal"/>
  </contact>

  <actuator>
    <general name="actuator1" joint="joint1" class="joint1"/>
    <general name="actuator2" joint="joint2" class="joint2"/>
    <general name="actuator3" joint="joint3" class="joint1"/>
    <general name="actuator4" joint="joint4" class="joint2"/>
    <general name="actuator5" joint="joint5" class="joint1"/>
    <general name="actuator6" joint="joint6" class="joint2"/>
    <general name="actuator7" joint="joint7" class="joint3"/>

    <position name="ffa0" joint="ffj0" class="base"/>
    <position name="ffa1" joint="ffj1" class="proximal"/>
    <position name="ffa2" joint="ffj2" class="medial"/>
    <position name="ffa3" joint="ffj3" class="distal"/>
    <position name="mfa0" joint="mfj0" class="base"/>
    <position name="mfa1" joint="mfj1" class="proximal"/>
    <position name="mfa2" joint="mfj2" class="medial"/>
    <position name="mfa3" joint="mfj3" class="distal"/>
    <position name="rfa0" joint="rfj0" class="base"/>
    <position name="rfa1" joint="rfj1" class="proximal"/>
    <position name="rfa2" joint="rfj2" class="medial"/>
    <position name="rfa3" joint="rfj3" class="distal"/>
    <position name="tha0" joint="thj0" class="thumb_base"/>
    <position name="tha1" joint="thj1" class="thumb_proximal"/>
    <position name="tha2" joint="thj2" class="thumb_medial"/>
    <position name="tha3" joint="thj3" class="thumb_distal"/>
  </actuator>
</mujoco>
