<mujoco model="ur10e_2f85_scene">
  <compiler angle="radian" autolimits="true"/>

  <option integrator="implicitfast" cone="elliptic" impratio="10"/>

  <statistic center="0.4 0 0.4" extent="1.2"/>

  <visual>
    <headlight diffuse="0.6 0.6 0.6" ambient="0.1 0.1 0.1" specular="0 0 0"/>
    <rgba haze="0.15 0.25 0.35 1"/>
    <global azimuth="120" elevation="-20"/>
  </visual>

  <asset>
    <material class="ur10e" name="black" rgba="0.033 0.033 0.033 1"/>
    <material class="ur10e" name="jointgray" rgba="0.278 0.278 0.278 1"/>
    <material class="ur10e" name="linkgray" rgba="0.82 0.82 0.82 1"/>
    <material class="ur10e" name="urblue" rgba="0.49 0.678 0.8 1"/>

    <material name="gripper_metal" rgba="0.58 0.58 0.58 1"/>
    <material name="gripper_silicone" rgba="0.1882 0.1882 0.1882 1"/>
    <material name="gripper_gray" rgba="0.4627 0.4627 0.4627 1"/>
    <material name="gripper_black" rgba="0.149 0.149 0.149 1"/>

    <texture type="skybox" builtin="gradient" rgb1="0.3 0.5 0.7" rgb2="0 0 0" width="512" height="3072"/>
    <texture type="2d" name="groundplane" builtin="checker" mark="edge" rgb1="0.2 0.3 0.4" rgb2="0.1 0.2 0.3"
      markrgb="0.8 0.8 0.8" width="300" height="300"/>
    <material name="groundplane" texture="groundplane" texuniform="true" texrepeat="5 5" reflectance="0.2"/>

    <mesh file="universal_robots_ur10e/assets/base_0.obj"/>
    <mesh file="universal_robots_ur10e/assets/base_1.obj"/>
    <mesh file="universal_robots_ur10e/assets/shoulder_0.obj"/>
    <mesh file="universal_robots_ur10e/assets/shoulder_1.obj"/>
    <mesh file="universal_robots_ur10e/assets/shoulder_2.obj"/>
    <mesh file="universal_robots_ur10e/assets/upperarm_0.obj"/>
    <mesh file="universal_robots_ur10e/assets/upperarm_1.obj"/>
    <mesh file="universal_robots_ur10e/assets/upperarm_2.obj"/>
    <mesh file="universal_robots_ur10e/assets/upperarm_3.obj"/>
    <mesh file="universal_robots_ur10e/assets/forearm_0.obj"/>
    <mesh file="universal_robots_ur10e/assets/forearm_1.obj"/>
    <mesh file="universal_robots_ur10e/assets/forearm_2.obj"/>
    <mesh file="universal_robots_ur10e/assets/forearm_3.obj"/>
    <mesh file="universal_robots_ur10e/assets/wrist1_0.obj"/>
    <mesh file="universal_robots_ur10e/assets/wrist1_1.obj"/>
    <mesh file="universal_robots_ur10e/assets/wrist1_2.obj"/>
    <mesh file="universal_robots_ur10e/assets/wrist2_0.obj"/>
    <mesh file="universal_robots_ur10e/assets/wrist2_1.obj"/>
    <mesh file="universal_robots_ur10e/assets/wrist2_2.obj"/>
    <mesh file="universal_robots_ur10e/assets/wrist3.obj"/>

    <mesh class="2f85" file="robotiq_2f85/assets/base_mount.stl"/>
    <mesh class="2f85" file="robotiq_2f85/assets/base.stl"/>
    <mesh class="2f85" file="robotiq_2f85/assets/driver.stl"/>
    <mesh class="2f85" file="robotiq_2f85/assets/coupler.stl"/>
    <mesh class="2f85" file="robotiq_2f85/assets/follower.stl"/>
    <mesh class="2f85" file="robotiq_2f85/assets/pad.stl"/>
    <mesh class="2f85" file="robotiq_2f85/assets/silicone_pad.stl"/>
    <mesh class="2f85" file="robotiq_2f85/assets/spring_link.stl"/>
  </asset>

  <default>
    <default class="ur10e">
      <material specular="0.5" shininess="0.25"/>
      <joint axis="0 1 0" range="-6.28319 6.28319" armature="0.1"/>
      <position ctrlrange="-6.2831 6.2831"/>
      <general biastype="affine" ctrlrange="-6.2831 6.2831" gainprm="5000" biasprm="0 -5000 -500"/>
      <default class="size4">
        <joint damping="10"/>
        <general forcerange="-330 330"/>
      </default>
      <default class="size3">
        <joint damping="5"/>
        <general forcerange="-150 150"/>
        <default class="size3_limited">
          <joint range="-3.1415 3.1415"/>
          <general ctrlrange="-3.1415 3.1415"/>
        </default>
      </default>
      <default class="size2">
        <joint damping="2"/>
        <general forcerange="-56 56"/>
      </default>
      <default class="visual">
        <geom type="mesh" contype="0" conaffinity="0" group="2"/>
      </default>
      <default class="collision">
        <geom type="capsule" group="3"/>
        <default class="eef_collision">
          <geom type="cylinder"/>
        </default>
      </default>
      <site size="0.001" rgba="0.5 0.5 0.5 0.3" group="4"/>
    </default>

    <default class="2f85">
      <mesh scale="0.001 0.001 0.001"/>
      <general biastype="affine"/>

      <joint axis="1 0 0"/>
      <default class="gripper_driver">
        <joint range="0 0.8" armature="0.005" damping="0.1" solimplimit="0.95 0.99 0.001" solreflimit="0.005 1"/>
      </default>
      <default class="gripper_follower">
        <joint range="-0.872664 0.872664" armature="0.001" pos="0 -0.018 0.0065" solimplimit="0.95 0.99 0.001" solreflimit="0.005 1"/>
      </default>
      <default class="gripper_spring_link">
        <joint range="-0.29670597283 0.8" armature="0.001" stiffness="0.05" springref="2.62" damping="0.00125"/>
      </default>
      <default class="gripper_coupler">
        <joint range="-1.57 0" armature="0.001" solimplimit="0.95 0.99 0.001" solreflimit="0.005 1"/>
      </default>

      <default class="gripper_visual">
        <geom type="mesh" contype="0" conaffinity="0" group="2"/>
      </default>
      <default class="gripper_collision">
        <geom type="mesh" group="3"/>
        <default class="gripper_pad_box1">
          <geom mass="0" type="box" pos="0 -0.0026 0.028125" size="0.011 0.004 0.009375" friction="1.5"
            solimp="0.95 0.99 0.001" solref="0.004 1" priority="1" rgba="0.55 0.55 0.55 1"/>
        </default>
        <default class="gripper_pad_box2">
          <geom mass="0" type="box" pos="0 -0.0026 0.009375" size="0.011 0.004 0.009375" friction="1.5"
            solimp="0.95 0.99 0.001" solref="0.004 1" priority="1" rgba="0.45 0.45 0.45 1"/>
        </default>
      </default>
    </default>
  </default>

  <worldbody>
    <light name="spotlight" mode="targetbodycom" target="wrist_2_link" pos="0 -1 2"/>
    <light pos="0 0 1.5" dir="0 0 -1" directional="true"/>
    <geom name="floor" size="0 0 0.05" type="plane" material="groundplane"/>

    <camera name="scene_cam" pos="1.2 0.0 0.8" quat="0.7071 0.0 0.7071 0.0"/>

    <body name="stool" pos="0.7 0 0.05">
      <geom type="box" size="0.04 0.04 0.05" rgba="0.6 0.6 0.6 1"/>
    </body>
    <body name="cube" pos="0.7 0 0.12">
      <freejoint/>
      <geom type="box" size="0.02 0.02 0.02" rgba="0.8 0.2 0.2 1" friction="0.8" density="8000"/>
    </body>

    <body name="base" quat="1 0 0 0" childclass="ur10e">
      <inertial mass="4.0" pos="0 0 0" diaginertia="0.0061063308908 0.0061063308908 0.01125"/>
      <geom mesh="base_0" material="black" class="visual"/>
      <geom mesh="base_1" material="jointgray" class="visual"/>
      <body name="shoulder_link" pos="0 0 0.181">
        <inertial pos="0 0 0" mass="7.778" diaginertia="0.0314743 0.0314743 0.0218756"/>
        <joint name="shoulder_pan_joint" class="size4" axis="0 0 1"/>
        <geom mesh="shoulder_0" material="urblue" class="visual"/>
        <geom mesh="shoulder_1" material="black" class="visual"/>
        <geom mesh="shoulder_2" material="jointgray" class="visual"/>
        <geom class="collision" size="0.078 0.08" pos="0 0 -0.05"/>
        <body name="upper_arm_link" pos="0 0.176 0" quat="1 0 1 0">
          <inertial pos="0 0 0.3065" mass="12.93" diaginertia="0.423074 0.423074 0.0363656"/>
          <joint name="shoulder_lift_joint" class="size4"/>
          <geom mesh="upperarm_0" material="black" class="visual"/>
          <geom mesh="upperarm_1" material="jointgray" class="visual"/>
          <geom mesh="upperarm_2" material="urblue" class="visual"/>
          <geom mesh="upperarm_3" material="linkgray" class="visual"/>
          <geom class="collision" pos="0 -0.05 0" quat="1 1 0 0" size="0.078 0.08"/>
          <geom class="collision" size="0.06 0.3" pos="0 0 0.3"/>
          <body name="forearm_link" pos="0 -0.137 0.613">
            <inertial pos="0 0 0.2855" mass="3.87" diaginertia="0.11059 0.11059 0.0108844"/>
            <joint name="elbow_joint" class="size3_limited"/>
            <geom mesh="forearm_0" material="urblue" class="visual"/>
            <geom mesh="forearm_1" material="black" class="visual"/>
            <geom mesh="forearm_2" material="jointgray" class="visual"/>
            <geom mesh="forearm_3" material="linkgray" class="visual"/>
            <geom class="collision" pos="0 0.08 0" quat="1 1 0 0" size="0.058 0.065"/>
            <geom class="collision" size="0.043 0.28" pos="0 0 0.29"/>
            <body name="wrist_1_link" pos="0 0 0.571" quat="1 0 1 0">
              <inertial pos="0 0.135 0" quat="0.5 0.5 -0.5 0.5" mass="1.96"
                diaginertia="0.0055125 0.00510825 0.00510825"/>
              <joint name="wrist_1_joint" class="size2"/>
              <geom mesh="wrist1_0" material="black" class="visual"/>
              <geom mesh="wrist1_1" material="urblue" class="visual"/>
              <geom mesh="wrist1_2" material="jointgray" class="visual"/>
              <geom class="collision" pos="0 0.06 0" quat="1 1 0 0" size="0.05 0.07"/>
              <body name="wrist_2_link" pos="0 0.135 0">
                <inertial pos="0 0 0.12" quat="0.5 0.5 -0.5 0.5" mass="1.96"
                  diaginertia="0.0055125 0.00510825 0.00510825"/>
                <joint name="wrist_2_joint" axis="0 0 1" class="size2"/>
                <geom mesh="wrist2_0" material="black" class="visual"/>
                <geom mesh="wrist2_1" material="urblue" class="visual"/>
                <geom mesh="wrist2_2" material="jointgray" class="visual"/>
                <geom class="collision" size="0.046 0.065" pos="0 0 0.05"/>
                <geom class="collision" pos="0 0.028 0.12" quat="1 1 0 0" size="0.046 0.043"/>
                <body name="wrist_3_link" pos="0 0 0.12">
                  <inertial pos="0 0.092 0" quat="0 1 -1 0" mass="0.202"
                    diaginertia="0.000204525 0.000144346 0.000144346"/>
                  <joint name="wrist_3_joint" class="size2"/>
                  <geom material="linkgray" mesh="wrist3" class="visual"/>
                  <geom class="eef_collision" pos="0 0.097 0" quat="1 1 0 0" size="0.046 0.02"/>
                  <site name="attachment_site" pos="0 0.1 0" quat="-1 1 0 0"/>

                  <body name="gripper_mount" pos="0 0.1 0" quat="-1 1 0 0">
                    <body name="gripper_base" pos="0 0 0.007" quat="1 0 0 1">
                      <geom type="box" size="0.03 0.03 0.02" rgba="0.2 0.2 0.2 1"/>
                      <site name="pinch" pos="0 0 0.12" type="sphere" group="5" rgba="0.9 0.9 0.9 1" size="0.005"/>
                      <body name="left_finger" pos="0 0.03 0.09">
                        <joint name="left_finger_slide" type="slide" axis="0 -1 0" range="0 0.04"/>
                        <geom type="box" size="0.012 0.003 0.02" rgba="0.1 0.1 0.1 1" friction="1.5"/>
                      </body>
                      <body name="right_finger" pos="0 -0.03 0.09">
                        <joint name="right_finger_slide" type="slide" axis="0 1 0" range="0 0.04"/>
                        <geom type="box" size="0.012 0.003 0.02" rgba="0.1 0.1 0.1 1" friction="1.5"/>
                      </body>
                    </body>
                  </body>
                </body>
              </body>
            </body>
          </body>
        </body>
      </body>
    </body>
  </worldbody>

  <contact>
    <exclude body1="wrist_3_link" body2="left_finger"/>
    <exclude body1="wrist_3_link" body2="right_finger"/>
    <exclude body1="gripper_base" body2="left_finger"/>
    <exclude body1="gripper_base" body2="right_finger"/>
  </contact>

  <tendon>
    <fixed name="gripper_split">
      <joint joint="right_finger_slide" coef="0.5"/>
      <joint joint="left_finger_slide" coef="0.5"/>
    </fixed>
  </tendon>

  <actuator>
    <general class="size4" name="shoulder_pan" joint="shoulder_pan_joint"/>
    <general class="size4" name="shoulder_lift" joint="shoulder_lift_joint"/>
    <general class="size3_limited" name="elbow" joint="elbow_joint"/>
    <general class="size2" name="wrist_1" joint="wrist_1_joint"/>
    <general class="size2" name="wrist_2" joint="wrist_2_joint"/>
    <general class="size2" name="wrist_3" joint="wrist_3_joint"/>
    <position name="fingers_actuator" tendon="gripper_split" kp="300" ctrlrange="0 0.04"/>
  </actuator>

  <keyframe>
    <key name="home" qpos="-1.5708 -1.5708 1.5708 -1.5708 -1.5708 0" ctrl="-1.5708 -1.5708 1.5708 -1.5708 -1.5708 0"/>
  </keyframe>
</mujoco>
